#VRML_SIM R2025a utf8

# Định nghĩa một robot mới có tên là demoRobot, với 2 tham số truyền vào là vị trí và hướng
PROTO demoRobot[
  field SFVec3f translation 0.331 0.123 0     # Vị trí ban đầu của robot
  field SFRotation rotation 1 0 0 1.52      # Góc xoay ban đầu của robot
] {
  Robot {
    translation IS translation           # Gán vị trí từ tham số truyền vào
    rotation IS rotation                 # Gán góc quay từ tham số truyền vào
    children [                           # Các thành phần con cấu thành robot

      # --- Thân chính ---
      Solid {
        name "body"                      # Tên phần thân
        translation 0 0.1 0              # Đặt thân lên cao khỏi mặt đất
        children [
          Shape {
            appearance Appearance {
              material Material {
                diffuseColor 1 0.8 0.2   # Màu vàng cam
              }
            }
            geometry Box {
              size 0.25 0.2 0.2          # Kích thước hình hộp
            }
          }
        ]
        boundingObject Box {
          size 0.25 0.2 0.2              # Hình dạng vật lý của thân để va chạm
        }
        physics Physics {}               # Bật mô phỏng vật lý
      }

      # --- Tay trái điều khiển bằng servo ---
      HingeJoint {
        jointParameters HingeJointParameters {
          axis 1 0 0                     # Xoay quanh trục X (gập lên xuống)
          anchor -0.18 0.15 0            # Tâm xoay nằm bên trái thân
        }
        device [
          RotationalMotor {
            name "left_arm_servo"        # Tên motor servo điều khiển tay trái
            maxVelocity 1.57             # Vận tốc tối đa (rad/s)
          }
        ]
        endPoint Solid {
          name "left_arm"
          translation -0.18 0.15 0       # Vị trí tay trái
          children [
            Shape {
              appearance Appearance {
                material Material {
                  diffuseColor 0.5 0.3 0.1   # Màu nâu
                }
              }
              geometry Box {
                size 0.05 0.05 0.1       # Kích thước tay
              }
            }
          ]
          boundingObject Box {
            size 0.05 0.05 0.1
          }
          physics Physics {}
        }
      }

      # --- Tay phải điều khiển bằng servo ---
      HingeJoint {
        jointParameters HingeJointParameters {
          axis 1 0 0
          anchor 0.18 0.15 0             # Gắn bên phải thân
        }
        device [
          RotationalMotor {
            name "right_arm_servo"
            maxVelocity 1.57
          }
        ]
        endPoint Solid {
          name "right_arm"
          translation 0.18 0.15 0
          children [
            Shape {
              appearance Appearance {
                material Material {
                  diffuseColor 0.5 0.3 0.1
                }
              }
              geometry Box {
                size 0.05 0.05 0.1
              }
            }
          ]
          boundingObject Box {
            size 0.05 0.05 0.1
          }
          physics Physics {}
        }
      }

      # --- Đầu xoay bằng servo ---
      HingeJoint {
        jointParameters HingeJointParameters {
          axis 0 1 0                     # Xoay quanh trục Y (quay trái/phải)
          anchor 0 0.25 0                # Gắn trên đầu thân
        }
        device [
          RotationalMotor {
            name "head_servo"
            maxVelocity 1.57
          }
        ]
        endPoint Solid {
          name "head"
          translation 0 0.25 0
          children [
            Shape {
              appearance Appearance {
                material Material {
                  diffuseColor 0.8 0.5 0.2
                }
              }
              geometry Box {
                size 0.06 0.06 0.06
              }
            }
          ]
          boundingObject Box {
            size 0.06 0.06 0.06
          }
          physics Physics {}
        }
      }

      # --- Bánh xe trái (có thể lăn) ---
      HingeJoint {
        parent "body"
        jointParameters HingeJointParameters {
          axis 1 0 0                     # Bánh quay quanh trục X (lăn về trước/sau)
          anchor -0.15 0.05 0         # Vị trí tâm bánh trái
        }
        device [
          RotationalMotor {
            name "left_motor"
            maxVelocity 10
          }
        ]
        endPoint Solid {
          name "left_wheel"
          translation -0.15 0.05 0.1
          rotation 0 1 0 1.5708          # Xoay hình bánh xe 90 độ quanh trục X (dựng đứng)
          children [
            Shape {
              appearance Appearance {
                material Material {
                  diffuseColor 0.1 0.1 0.1  # Màu đen
                }
              }
              geometry Cylinder {
                radius 0.05
                height 0.03
              }
            }
          ]
          boundingObject Cylinder {
            radius 0.05
            height 0.03
          }
          physics Physics {}
        }
      }

      # --- Bánh xe phải (có thể lăn) ---
      HingeJoint {
        parent "body"
        jointParameters HingeJointParameters {
          axis 1 0 0
          anchor 0.15 0.05 0
        }
        device [
          RotationalMotor {
            name "right_motor"
            maxVelocity 10
          }
        ]
        endPoint Solid {
          name "right_wheel"
          translation 0.15 0.05 0.1
          rotation 0 1 0 1.5708
          children [
            Shape {
              appearance Appearance {
                material Material {
                  diffuseColor 0.1 0.1 0.1
                }
              }
              geometry Cylinder {
                radius 0.05
                height 0.03
              }
            }
          ]
          boundingObject Cylinder {
            radius 0.05
            height 0.03
          }
          physics Physics {}
        }
      }
    ]
    controller "wall-e-controller"  # Tên file controller Python
  }
}
