#VRML_SIM R2025a utf8

# Định nghĩa một robot có tên là demoRobot với hai tham số đầu vào: vị trí và góc xoay
PROTO demoRobot[
  field SFVec3f translation 0.331 0.123 0     # Vị trí ban đầu của robot trong không gian 3D
  field SFRotation rotation 1 0 0 1.52        # Góc xoay ban đầu của robot (quanh trục X)
] {
  Robot {
    translation IS translation                 # Gán giá trị vị trí từ tham số đầu vào
    rotation IS rotation                       # Gán giá trị góc xoay từ tham số đầu vào

    children [

      # --- Thân chính của robot ---
      Solid {
        name "body"                            # Đặt tên thân là 'body'
        translation 0 0.1 1                    # Dời thân lên cao để không nằm trên mặt đất

        children [

          # Hình khối thể hiện thân robot
          Shape {
            appearance Appearance {
              material Material {
                diffuseColor 1 0.8 0.2         # Màu thân: vàng cam
              }
            }
            geometry Box {
              size 0.25 0.2 0.2                # Kích thước thân: chiều rộng, cao, sâu
            }
          },

          # --- Tay trái gắn bằng servo ---
          HingeJoint {
            jointParameters HingeJointParameters {
              axis 1 0 0                       # Trục xoay là trục X (gập lên xuống)
              anchor -0.18 0.05 0              # Vị trí bản lề gắn tay trái
            }
            device [
              RotationalMotor {
                name "left_arm_servo"          # Tên động cơ điều khiển tay trái
                maxVelocity 1.57               # Tốc độ quay tối đa
              }
            ]
            endPoint Solid {
              name "left_arm"
              translation -0.18 0.05 0         # Vị trí tay trái
              children [
                Shape {
                  appearance Appearance {
                    material Material {
                      diffuseColor 0.5 0.3 0.1 # Màu tay: nâu đất
                    }
                  }
                  geometry Box {
                    size 0.05 0.05 0.1         # Kích thước tay trái
                  }
                }
              ]
              boundingObject Box {
                size 0.05 0.05 0.1             # Vật thể dùng để mô phỏng va chạm
              }
              physics Physics {}               # Kích hoạt mô phỏng vật lý cho tay
            }
          },

          # --- Tay phải ---
          HingeJoint {
            jointParameters HingeJointParameters {
              axis 1 0 0
              anchor 0.18 0.05 0
            }
            device [
              RotationalMotor {
                name "right_arm_servo"
                maxVelocity 1.57
              }
            ]
            endPoint Solid {
              name "right_arm"
              translation 0.18 0.05 0
              children [
                Shape {
                  appearance Appearance {
                    material Material {
                      diffuseColor 0.5 0.3 0.1
                    }
                  }
                  geometry Box {
                    size 0.05 0.05 0.1
                  }
                }
              ]
              boundingObject Box {
                size 0.05 0.05 0.1
              }
              physics Physics {}
            }
          },

          # --- Đầu robot gắn servo quay trái/phải ---
          HingeJoint {
            jointParameters HingeJointParameters {
              axis 0 1 0                       # Trục Y để quay trái/phải
              anchor 0 0.15 0                  # Gắn đầu lên phía trên thân
            }
            device [
              RotationalMotor {
                name "head_servo"
                maxVelocity 1.57
              }
            ]
            endPoint Solid {
              name "head"
              translation 0 0.15 0
              children [
                Shape {
                  appearance Appearance {
                    material Material {
                      diffuseColor 0.8 0.5 0.2 # Màu vàng đậm
                    }
                  }
                  geometry Box {
                    size 0.06 0.06 0.06         # Kích thước đầu robot
                  }
                }
              ]
              boundingObject Box {
                size 0.06 0.06 0.06
              }
              physics Physics {}
            }
          },

          # --- Bánh xe trái ---
          HingeJoint {
            jointParameters HingeJointParameters {
              axis 1 0 0                        # Trục quay là trục X (quay tới lui)
              anchor -0.15 -0.1 0.1             # Gắn gần sát thân
            }
            device [
              RotationalMotor {
                name "left_motor"
                maxVelocity 10
              }
            ]
            endPoint Solid {
              name "left_wheel"
              translation -0.15 -0.1 0.1
              rotation 0 1 0 1.5708             # Quay hình trụ để nằm ngang
              children [
                Shape {
                  appearance Appearance {
                    material Material {
                      diffuseColor 0.1 0.1 0.1  # Màu bánh xe: đen
                    }
                  }
                  geometry Cylinder {
                    radius 0.05
                    height 0.03
                  }
                }
              ]
              boundingObject Cylinder {
                radius 0.05
                height 0.03
              }
              physics Physics {}
            }
          },

          # --- Bánh xe phải ---
          HingeJoint {
            jointParameters HingeJointParameters {
              axis 1 0 0
              anchor 0.15 -0.1 0.1
            }
            device [
              RotationalMotor {
                name "right_motor"
                maxVelocity 10
              }
            ]
            endPoint Solid {
              name "right_wheel"
              translation 0.15 -0.1 0.1
              rotation 0 1 0 1.5708
              children [
                Shape {
                  appearance Appearance {
                    material Material {
                      diffuseColor 0.1 0.1 0.1
                    }
                  }
                  geometry Cylinder {
                    radius 0.05
                    height 0.03
                  }
                }
              ]
              boundingObject Cylinder {
                radius 0.05
                height 0.03
              }
              physics Physics {}
            }
          }
        ]

        # Khối vật lý dùng để tính toán va chạm và khối lượng thân chính
        boundingObject Box {
          size 0.25 0.2 0.2                     # Kích thước khớp với hình dạng thân
        }

        # Mô phỏng vật lý: trọng lượng 2kg
        physics Physics {
          mass 2.0
        }
      }
    ]

    # Tên controller Python/C/C++ sẽ điều khiển robot này
    controller "wall-e-controller"
  }
}
